<?xml version="1.0"?>
<robot name="roco_arm">
  <link name="base_link">
    <visual>
      <geometry>
        <cylinder length="0.06" radius="0.1"/>
      </geometry>
    </visual>
  </link>

  <link name="first_segment">
    <visual>
      <geometry>
        <box size="0.6 0.05 0.1"/>
      </geometry>
      <origin rpy="0 0 0" xyz="-0.3 0 0" />
    </visual>
  </link>

  <joint name="base_to_first" type="revolute">
    <axis xyz="0 1 0" />
    <limit effort="1000" lower="0" upper="3.14" velocity="0.5" />
    <parent link="base_link"/>
    <child link="first_segment"/>
    <origin xyz="0 0 0.03" />
  </joint>
</robot>

